Workbook

Sheet LeiaMe
A1: CICLO · Modelo financeiro e de metas
A3: Como usar: mude só as células em AZUL nas abas Premissas, Calendario, Infra e Metas. O resto recalcula.
A4: Abas: Resumo (os 3 cenários lado a lado) · Premissas · Calendario · Pessimista/Base/Otimista (mês a mês) · Metas (quantas abordagens por dia) · Infra (quantas contas cabem antes de pagar mais).
A5: Cores: azul = você pode mudar · preto = fórmula · verde = veio de outra aba.
A6: Marcadores: [M] medido no banco ou no código · [P] preço público conferido em 28-30/09/2026 · [E] estimativa minha · [H] hipótese de funil que só o campo confirma.
A7: O que NÃO está no modelo: WhatsApp automático (fora até 20 assinantes, docs/87 E1), anúncio pago, IA externa (o assistente roda no Motor próprio, sem custo por pergunta), funcionário.
A8: Cuidado: as taxas de funil são hipóteses. Depois do alpha (10 contas) troque os azuis da coluna Base pelos números medidos.
A9: Fontes de preço: supabase.com/pricing · vercel.com/pricing · resend.com/pricing · sentry.io/pricing · upstash.com/pricing (não usado em produção) · docs/18 e docs/87 do repositório.
A10: Mercado Pago: a tabela oficial bloqueou a leitura automática. A taxa do cartão recorrente está estimada e precisa ser conferida no painel.

Sheet Resumo
A1: CICLO · Resumo dos três cenários (Out/26 a Dez/28)
A2: Todos os números vêm das abas de cenário. Mude as premissas e isto recalcula.
A4: Indicador | B4: Pessimista | C4: Base | D4: Otimista
A5: Contas criadas até Dez/26 | B5: =Pessimista!E17 | C5: =Base!E17 | D5: =Otimista!E17
A6: Pagantes em Jan/27 (lançamento) | B6: =Pessimista!F23 | C6: =Base!F23 | D6: =Otimista!F23
A7: Pagantes em Jun/27 | B7: =Pessimista!K23 | C7: =Base!K23 | D7: =Otimista!K23
A8: Pagantes em Dez/27 | B8: =Pessimista!Q23 | C8: =Base!Q23 | D8: =Otimista!Q23
A9: Pagantes em Dez/28 | B9: =Pessimista!C54 | C9: =Base!C54 | D9: =Otimista!C54
A10: Receita bruta mensal em Jun/27 | B10: =Pessimista!K28 | C10: =Base!K28 | D10: =Otimista!K28
A11: Receita bruta mensal em Dez/27 | B11: =Pessimista!Q28 | C11: =Base!Q28 | D11: =Otimista!Q28
A12: Receita bruta mensal em Dez/28 | B12: =Pessimista!C55 | C12: =Base!C55 | D12: =Otimista!C55
A13: Resultado operacional em Dez/27 | B13: =Pessimista!Q41 | C13: =Base!Q41 | D13: =Otimista!Q41
A14: Resultado operacional em Dez/28 | B14: =Pessimista!C56 | C14: =Base!C56 | D14: =Otimista!C56
A15: Primeiro mês no azul (operacional) | B15: =Pessimista!C57 | C15: =Base!C57 | D15: =Otimista!C57
A16: Caixa acumulado volta ao positivo em | B16: =Pessimista!C58 | C16: =Base!C58 | D16: =Otimista!C58
A17: Maior exposição de caixa | B17: =Pessimista!C59 | C17: =Base!C59 | D17: =Otimista!C59
A18: Caixa acumulado em Dez/27 | B18: =Pessimista!Q44 | C18: =Base!Q44 | D18: =Otimista!Q44
A19: Caixa acumulado em Dez/28 | B19: =Pessimista!C60 | C19: =Base!C60 | D19: =Otimista!C60
A20: Retorno sobre o total gasto | B20: =Pessimista!C61 | C20: =Base!C61 | D20: =Otimista!C61
A21: Receita líquida por pagante | B21: =Pessimista!C63 | C21: =Base!C63 | D21: =Otimista!C63
A22: LTV descontando o suporte | B22: =Pessimista!C65 | C22: =Base!C65 | D22: =Otimista!C65
A23: CAC contando o seu tempo | B23: =Pessimista!C67 | C23: =Base!C67 | D23: =Otimista!C67
A24: LTV / CAC | B24: =Pessimista!C68 | C24: =Base!C68 | D24: =Otimista!C68

Sheet Premissas
A1: CICLO · Premissas (edite só as células azuis)
A2: Azul = valor que você pode mudar. Preto = fórmula. Verde = vem de outra aba. [M] medido · [E] estimado · [P] preço público conferido em 28-30/09/2026 · [H] hipótese de funil a validar.
A4: Premissa global | C4: Valor | E4: Fonte / nota
A5: Câmbio (R$ por US$) | C5: 5.22 | E5: [P] cotação de 28/09/2026 (Bloomberg Línea / MoneyTimes). Faixa 52 semanas: 4,89 a 5,61
A6: Preço Solo (R$/mês) | C6: 49 | E6: docs/87 D2: 1 profissional, tudo incluído
A7: Preço Equipe (R$/mês) | C7: 99 | E7: docs/87 D2: até 5 profissionais, tudo incluído
A8: % das assinaturas pagas no cartão (Mercado Pago preapproval) | C8: 0.9 | E8: [E] o código usa preapproval (recorrência no cartão). O resto vai por Pix
A9: Taxa efetiva do cartão recorrente | C9: 0.04 | E9: [E] NÃO verificado: a tabela oficial do Mercado Pago bloqueou a leitura. Fontes de terceiros dizem 2% a 5%. Conferir no painel quando a conta CNPJ existir
A10: Taxa do Pix | C10: 0.0099 | E10: [P] Mercado Pago, 0,99% (0,49% acima de R$ 15 mil/mês em CNPJ novo)
A11: Imposto em % (0 enquanto MEI) | C11: 0 | E11: Ao virar ME: 6% (Anexo III) ou 15,5% (Anexo V); contador confirma
A12: Supabase Pro (US$/mês, inclui US$ 10 de crédito de computação) | C12: 25 | E12: [P] supabase.com/pricing: a partir de US$ 25. 8 GB de banco, 250 GB de saída, backup de 7 dias
A13: Vercel Pro (US$/mês por usuário) | C13: 20 | E13: [P] vercel.com/pricing. Inclui US$ 20 de crédito de uso. 1 usuário (você)
A14: Crédito de uso incluído na Vercel Pro (US$) | C14: 20 | E14: [P] vercel.com/pricing
A15: Uso Vercel por conta (US$/mês) | C15: =Infra!C12 | E15: Vem da aba Infra (requisições x CPU x preço)
A16: DAS do MEI (R$/mês). Vira contador + 6% só ao passar de ~100 pagantes | C16: 86.05 | E16: [P] Receita: R$ 86,05 (serviços, 2026). Teto MEI R$ 81 mil/ano (~110 pagantes)
A17: Salário mínimo 2026 (R$) | C17: 1621 | E17: [E] confirmar. Base do pró-labore mínimo
A18: INSS sobre o pró-labore (custo PESSOAL; 0 = não conta) | C18: 0 | E18: Fica em 0: é a sua contribuição, não custo do produto. Para ver o efeito, ponha 11% (11% de 1 salário mínimo = R$ 178)
A19: Domínio seuciclo.com.br (R$/mês) | C19: =40/12 | E19: [E] cerca de R$ 40 por ano no registro.br
A20: E-mail próprio do produto (R$/mês) | C20: 0 | E20: Fica em 0: dá para usar e-mail gratuito. Workspace custaria ~R$ 30
A21: Resend Pro (US$/mês) | C21: 20 | E21: [P] resend.com/pricing: grátis até 3.000 e-mails/mês e 100/dia. Pro US$ 20 = 50.000
A22: Contas a partir das quais o Resend grátis não basta | C22: 120 | E22: [E] ~25 e-mails por conta/mês contra o teto de 3.000
A23: Sentry Team (US$/mês) | C23: 26 | E23: [P] sentry.io/pricing: grátis 5.000 erros/mês. Team US$ 26
A24: Contas a partir das quais o Sentry grátis não basta | C24: 100 | E24: [E]
A25: Contas até onde o Supabase Micro (incluso) aguenta | C25: 150 | E25: [E] sem teste de carga. Regra: subir quando CPU > 70% ou cache < 99%
A26: Acréscimo ao passar para Small (US$/mês) | C26: 5 | E26: [P] Small ~US$ 15 menos o crédito de US$ 10
A27: Contas até onde o Small aguenta | C27: 400 | E27: [E]
A28: Acréscimo ao passar para Medium (US$/mês) | C28: 50 | E28: [P] Medium ~US$ 60 menos o crédito
A29: Contas até onde o Medium aguenta | C29: 1000 | E29: [E]
A30: Acréscimo ao passar para Large (US$/mês) | C30: 100 | E30: [P] Large ~US$ 110 menos o crédito
A31: Custo em dinheiro por dia de prospecção (R$) | C31: 25 | E31: [E] transporte, estacionamento, café
... A44: Abordagens qualificadas por dia de rua | C44: 12 | E44: [E] dono presente, salão de 1 a 3 profissionais. Ver aba Metas
A46: Premissa por cenário | B46: Pessimista | C46: Base | D46: Otimista | E46: Fonte / nota
A47: Dono aceita conversar de verdade (5 min ou mais) | B47: 0.4 | C47: 0.55 | D47: 0.7 | E47: [H] das abordagens. Porta fechada, cliente na cadeira e dono ausente contam como não
A48: Cria a conta na hora ou em 48 h | B48: 0.2 | C48: 0.3 | D48: 0.4 | E48: [H] das conversas. Ajuda: 2 meses grátis, sem cartão, cadastro assistido no celular dele
A49: Ativa: importa a base e chama alguém em 14 dias | B49: 0.45 | C49: 0.55 | D49: 0.65 | E49: [H] docs/87 §5: 60% importam em 7 dias, 50% chamam em 14
A50: Vira pagante no lançamento (das contas criadas) | B50: 0.08 | C50: 0.15 | D50: 0.25 | E50: [P] teste sem cartão: mediana 14%, faixa 8% a 22% (Userpilot, First Page Sage, ShNo 2026)
A51: Cancelamento mensal de quem paga | B51: 0.06 | C51: 0.04 | D51: 0.025 | E51: [P] SaaS para pequena empresa: 3% a 5% ao mês, média 4,5% (RetentionCheck 2026)
A52: % dos pagantes no plano Solo | B52: 0.8 | C52: 0.75 | D52: 0.65 | E52: [H] barbearia e salão pequeno: maioria com 1 profissional
A53: Contas novas que cada pagante traz por mês | B53: 0.02 | C53: 0.05 | D53: 0.1 | E53: [H] barbeiro conhece barbeiro (docs/56). Zero antes de ter pagante
A54: Contas novas por mês de parceiro, conteúdo e busca (só após o lançamento) | B54: 0 | C54: 6 | D54: 20 | E54: [H] distribuidora, escola de barbeiro, Instagram (docs/18 G.1)

Sheet Calendario
A1: CICLO · Calendário (docs/87: alpha 26/10, pública 09/11, cortesia até 12/12, oficial 11/01/2027)
A4: Item | B4: Unidade | C4: Out/26 | D4: Nov/26 | E4: Dez/26 | F4: Jan/27 | G4: Fev/27 | H4: Mar/27 | I4: Abr/27 | J4: Mai/27 | K4: Jun/27 | L4: Jul/27 | M4: Ago/27 | N4: Set/27 | O4: Out/27 | P4: Nov/27 | Q4: Dez/27 | R4: Jan/28 | S4: Fev/28 | T4: Mar/28 | U4: Abr/28 | V4: Mai/28 | W4: Jun/28 | X4: Jul/28 | Y4: Ago/28 | Z4: Set/28 | AA4: Out/28 | AB4: Nov/28 | AC4: Dez/28
A5: Data | C5: 2026-10-01 | D5: 2026-11-01 | E5: 2026-12-01 | F5: 2027-01-01 | G5: 2027-02-01 | H5: 2027-03-01 | I5: 2027-04-01 | J5: 2027-05-01 | K5: 2027-06-01 | L5: 2027-07-01 | M5: 2027-08-01 | N5: 2027-09-01 | O5: 2027-10-01 | P5: 2027-11-01 | Q5: 2027-12-01 | R5: 2028-01-01 | S5: 2028-02-01 | T5: 2028-03-01 | U5: 2028-04-01 | V5: 2028-05-01 | W5: 2028-06-01 | X5: 2028-07-01 | Y5: 2028-08-01 | Z5: 2028-09-01 | AA5: 2028-10-01 | AB5: 2028-11-01 | AC5: 2028-12-01
A6: Fase | C6: Alpha (até 10 contas) | D6: Janela pública (ondas) | E6: Cortesia; sem cobrança | F6: Lançamento oficial 11/01 | G6: Pós-lançamento | H6: Pós-lançamento | I6: Pós-lançamento | J6: Pós-lançamento | K6: Pós-lançamento | L6: Pós-lançamento | M6: Pós-lançamento | N6: Pós-lançamento | O6: Pós-lançamento | P6: Pós-lançamento | Q6: Pós-lançamento | R6: Pós-lançamento | S6: Pós-lançamento | T6: Pós-lançamento | U6: Pós-lançamento | V6: Pós-lançamento | W6: Pós-lançamento | X6: Pós-lançamento | Y6: Pós-lançamento | Z6: Pós-lançamento | AA6: Pós-lançamento | AB6: Pós-lançamento | AC6: Pós-lançamento
A7: Dias de rua no mês | B7: dias | C7: 20 | D7: 20 | E7: 14 | F7: 20 | G7: 20 | H7: 20 | I7: 20 | J7: 20 | K7: 20 | L7: 20 | M7: 20 | N7: 20 | O7: 20 | P7: 20 | Q7: 14 | R7: 20 | S7: 20 | T7: 20 | U7: 20 | V7: 20 | W7: 20 | X7: 20 | Y7: 20 | Z7: 20 | AA7: 20 | AB7: 20 | AC7: 14
A8: Depois do lançamento (1 = sim) | C8: 1 | D8: 1 | E8: 1 | F8: 1 | G8: 1 | H8: 1 | I8: 1 | J8: 1 | K8: 1 | L8: 1 | M8: 1 | N8: 1 | O8: 1 | P8: 1 | Q8: 1 | R8: 1 | S8: 1 | T8: 1 | U8: 1 | V8: 1 | W8: 1 | X8: 1 | Y8: 1 | Z8: 1 | AA8: 1 | AB8: 1 | AC8: 1
A9: Mês do lançamento (1 = sim) | C9: 0 | D9: 0 | E9: 0 | F9: 0 | G9: 0 | H9: 0 | I9: 0 | J9: 0 | K9: 0 | L9: 0 | M9: 0 | N9: 0 | O9: 0 | P9: 0 | Q9: 0 | R9: 0 | S9: 0 | T9: 0 | U9: 0 | V9: 0 | W9: 0 | X9: 0 | Y9: 0 | Z9: 0 | AA9: 0 | AB9: 0 | AC9: 0
A10: Primeiro mês (1 = sim) | C10: 1 | D10: 0 | E10: 0 | F10: 0 | G10: 0 | H10: 0 | I10: 0 | J10: 0 | K10: 0 | L10: 0 | M10: 0 | N10: 0 | O10: 0 | P10: 0 | Q10: 0 | R10: 0 | S10: 0 | T10: 0 | U10: 0 | V10: 0 | W10: 0 | X10: 0 | Y10: 0 | Z10: 0 | AA10: 0 | AB10: 0 | AC10: 0
A11: Parceiros e conteúdo ativos (1 = sim) | C11: =C8 | D11: =D8 | E11: =E8 | F11: =F8 | G11: =G8 | H11: =H8 | I11: =I8 | J11: =J8 | ... AC11: =AC8

Sheet Pessimista
A1: CICLO · Projeção mês a mês · cenário Pessimista
A2: Tudo aqui é fórmula. Mude as premissas na aba Premissas e no Calendário.
A4: Linha | B4: Unid. | C4: Out/26 | D4: Nov/26 | E4: Dez/26 | F4: Jan/27 | G4: Fev/27 | H4: Mar/27 | I4: Abr/27 | J4: Mai/27 | K4: Jun/27 | L4: Jul/27 | M4: Ago/27 | N4: Set/27 | O4: Out/27 | P4: Nov/27 | Q4: Dez/27 | R4: Jan/28 | S4: Fev/28 | T4: Mar/28 | U4: Abr/28 | V4: Mai/28 | W4: Jun/28 | X4: Jul/28 | Y4: Ago/28 | Z4: Set/28 | AA4: Out/28 | AB4: Nov/28 | AC4: Dez/28
A5: Prospecção e contas
A6: Fase | C6: =Calendario!C6 | D6: =Calendario!D6 | E6: =Calendario!E6 | F6: =Calendario!F6 | G6: =Calendario!G6 | H6: =Calendario!H6 | I6: =Calendario!I6 | J6: =Calendario!J6 | ... AC6: =Calendario!AC6
A7: Dias de rua | B7: dias | C7: =Calendario!C7 | D7: =Calendario!D7 | E7: =Calendario!E7 | F7: =Calendario!F7 | G7: =Calendario!G7 | H7: =Calendario!H7 | I7: =Calendario!I7 | J7: =Calendario!J7 | ... AC7: =Calendario!AC7
A8: Abordagens | B8: n | C8: =C7*Premissas!$C$44 | D8: =D7*Premissas!$C$44 | E8: =E7*Premissas!$C$44 | F8: =F7*Premissas!$C$44 | G8: =G7*Premissas!$C$44 | H8: =H7*Premissas!$C$44 | I8: =I7*Premissas!$C$44 | J8: =J7*Premissas!$C$44 | ... AC8: =AC7*Premissas!$C$44
A9: Conversas de verdade | B9: n | C9: =C8*Premissas!$B$47 | D9: =D8*Premissas!$B$47 | E9: =E8*Premissas!$B$47 | F9: =F8*Premissas!$B$47 | G9: =G8*Premissas!$B$47 | H9: =H8*Premissas!$B$47 | I9: =I8*Premissas!$B$47 | J9: =J8*Premissas!$B$47 | ... AC9: =AC8*Premissas!$B$47
A10: Contas por prospecção | B10: n | C10: =C9*Premissas!$B$48 | D10: =D9*Premissas!$B$48 | E10: =E9*Premissas!$B$48 | F10: =F9*Premissas!$B$48 | G10: =G9*Premissas!$B$48 | H10: =H9*Premissas!$B$48 | I10: =I9*Premissas!$B$48 | J10: =J9*Premissas!$B$48 | ... AC10: =AC9*Premissas!$B$48
A11: Contas por indicação, parceiros e conteúdo | B11: n | C11: =0*Premissas!$B$53+Calendario!C11*Premissas!$B$54 | D11: =C23*Premissas!$B$53+Calendario!D11*Premissas!$B$54 | E11: =D23*Premissas!$B$53+Calendario!E11*Premissas!$B$54 | F11: =E23*Premissas!$B$53+Calendario!F11*Premissas!$B$54 | G11: =F23*Premissas!$B$53+Calendario!G11*Premissas!$B$54 | H11: =G23*Premissas!$B$53+Calendario!H11*Premissas!$B$54 | I11: =H23*Premissas!$B$53+Calendario!I11*Premissas!$B$54 | J11: =I23*Premissas!$B$53+Calendario!J11*Premissas!$B$54 | K11: =J23*Premissas!$B$53+Calendario!K11*Premissas!$B$54 | ... AC11: =AB23*Premissas!$B$53+Calendario!AC11*Premissas!$B$54
A12: Contas do alpha (convidadas) | B12: n | C12: =Calendario!C10*Premissas!$C$41 | D12: =Calendario!D10*Premissas!$C$41 | E12: =Calendario!E10*Premissas!$C$41 | F12: =Calendario!F10*Premissas!$C$41 | G12: =Calendario!G10*Premissas!$C$41 | H12: =Calendario!H10*Premissas!$C$41 | I12: =Calendario!I10*Premissas!$C$41 | J12: =Calendario!J10*Premissas!$C$41 | ... AC12: =Calendario!AC10*Premissas!$C$41
A13: Demanda total de contas | B13: n | C13: =C10+C11+C12 | D13: =D10+D11+D12 | E13: =E10+E11+E12 | F13: =F10+F11+F12 | G13: =G10+G11+G12 | H13: =H10+H11+H12 | I13: =I10+I11+I12 | J13: =J10+J11+J12 | ... AC13: =AC10+AC11+AC12
A14: Capacidade de atender | B14: n | C14: =IF(Calendario!C8=0,MAX(0,Premissas!$C$42-0),Premissas!$C$43) | D14: =IF(Calendario!D8=0,MAX(0,Premissas!$C$42-C17),Premissas!$C$43) | E14: =IF(Calendario!E8=0,MAX(0,Premissas!$C$42-D17),Premissas!$C$43) | F14: =IF(Calendario!F8=0,MAX(0,Premissas!$C$42-E17),Premissas!$C$43) | G14: =IF(Calendario!G8=0,MAX(0,Premissas!$C$42-F17),Premissas!$C$43) | H14: =IF(Calendario!H8=0,MAX(0,Premissas!$C$42-G17),Premissas!$C$43) | I14: =IF(Calendario!I8=0,MAX(0,Premissas!$C$42-H17),Premissas!$C$43) | J14: =IF(Calendario!J8=0,MAX(0,Premissas!$C$42-I17),Premissas!$C$43) | K14: =IF(Calendario!K8=0,MAX(0,Premissas!$C$42-J17),Premissas!$C$43) | ... AC14: =IF(Calendario!AC8=0,MAX(0,Premissas!$C$42-AB17),Premissas!$C$43)
A15: Contas criadas | B15: n | C15: =MIN(C13,C14) | D15: =MIN(D13,D14) | E15: =MIN(E13,E14) | F15: =MIN(F13,F14) | G15: =MIN(G13,G14) | H15: =MIN(H13,H14) | I15: =MIN(I13,I14) | J15: =MIN(J13,J14) | ... AC15: =MIN(AC13,AC14)
A16: Fila de espera gerada | B16: n | C16: =C13-C15 | D16: =D13-D15 | E16: =E13-E15 | F16: =F13-F15 | G16: =G13-G15 | H16: =H13-H15 | I16: =I13-I15 | J16: =J13-J15 | ... AC16: =AC13-AC15
A17: Contas acumuladas | B17: n | C17: =0+C15 | D17: =C17+D15 | E17: =D17+E15 | F17: =E17+F15 | G17: =F17+G15 | H17: =G17+H15 | I17: =H17+I15 | J17: =I17+J15 | K17: =J17+K15 | ... AC17: =AB17+AC15
A18: Contas ativas novas | B18: n | C18: =C15*Premissas!$B$49 | D18: =D15*Premissas!$B$49 | E18: =E15*Premissas!$B$49 | F18: =F15*Premissas!$B$49 | G18: =G15*Premissas!$B$49 | H18: =H15*Premissas!$B$49 | I18: =I15*Premissas!$B$49 | J18: =J15*Premissas!$B$49 | ... AC18: =AC15*Premissas!$B$49
A19: Pagantes
A20: Pagantes no início | B20: n | C20: =0 | D20: =C23 | E20: =D23 | F20: =E23 | G20: =F23 | H20: =G23 | I20: =H23 | J20: =I23 | K20: =J23 | ... AC20: =AB23
A21: Novos pagantes | B21: n1 | C21: =Calendario!C9*0*Premissas!$B$50+(Calendario!C8-Calendario!C9)*0*Premissas!$B$50 | D21: =Calendario!D9*C17*Premissas!$B$50+(Calendario!D8-Calendario!D9)*C15*Premissas!$B$50 | E21: =Calendario!E9*D17*Premissas!$B$50+(Calendario!E8-Calendario!E9)*D15*Premissas!$B$50 | F21: =Calendario!F9*E17*Premissas!$B$50+(Calendario!F8-Calendario!F9)*E15*Premissas!$B$50 | G21: =Calendario!G9*F17*Premissas!$B$50+(Calendario!G8-Calendario!G9)*F15*Premissas!$B$50 | H21: =Calendario!H9*G17*Premissas!$B$50+(Calendario!H8-Calendario!H9)*G15*Premissas!$B$50 | I21: =Calendario!I9*H17*Premissas!$B$50+(Calendario!I8-Calendario!I9)*H15*Premissas!$B$50 | J21: =Calendario!J9*I17*Premissas!$B$50+(Calendario!J8-Calendario!J9)*I15*Premissas!$B$50 | K21: =Calendario!K9*J17*Premissas!$B$50+(Calendario!K8-Calendario!K9)*J15*Premissas!$B$50 | ... AC21: =Calendario!AC9*AB17*Premissas!$B$50+(Calendario!AC8-Calendario!AC9)*AB15*Premissas!$B$50
A22: Cancelamentos | B22: n1 | C22: =C20*Premissas!$B$51 | D22: =D20*Premissas!$B$51 | E22: =E20*Premissas!$B$51 | F22: =F20*Premissas!$B$51 | G22: =G20*Premissas!$B$51 | H22: =H20*Premissas!$B$51 | I22: =I20*Premissas!$B$51 | J22: =J20*Premissas!$B$51 | ... AC22: =AC20*Premissas!$B$51
A23: Pagantes no fim | B23: n1 | C23: =C20+C21-C22 | D23: =D20+D21-D22 | E23: =E20+E21-E22 | F23: =F20+F21-F22 | G23: =G20+G21-G22 | H23: =H20+H21-H22 | I23: =I20+I21-I22 | J23: =J20+J21-J22 | ... AC23: =AC20+AC21-AC22
A24: Pagantes médios | B24: n1 | C24: =(C20+C23)/2 | D24: =(D20+D23)/2 | E24: =(E20+E23)/2 | F24: =(F20+F23)/2 | G24: =(G20+G23)/2 | H24: =(H20+H23)/2 | I24: =(I20+I23)/2 | J24: =(J20+J23)/2 | ... AC24: =(AC20+AC23)/2
A25: no Solo | B25: n1 | C25: =C24*Premissas!$B$52 | D25: =D24*Premissas!$B$52 | E25: =E24*Premissas!$B$52 | F25: =F24*Premissas!$B$52 | G25: =G24*Premissas!$B$52 | H25: =H24*Premissas!$B$52 | I25: =I24*Premissas!$B$52 | J25: =J24*Premissas!$B$52 | ... AC25: =AC24*Premissas!$B$52
A26: no Equipe | B26: n1 | C26: =C24-C25 | D26: =D24-D25 | E26: =E24-E25 | F26: =F24-F25 | G26: =G24-G25 | H26: =H24-H25 | I26: =I24-I25 | J26: =J24-J25 | ... AC26: =AC24-AC25
A27: Receita
A28: Receita bruta | B28: brl | C28: =C25*Premissas!$C$6+C26*Premissas!$C$7 | D28: =D25*Premissas!$C$6+D26*Premissas!$C$7 | E28: =E25*Premissas!$C$6+E26*Premissas!$C$7 | F28: =F25*Premissas!$C$6+F26*Premissas!$C$7 | G28: =G25*Premissas!$C$6+G26*Premissas!$C$7 | H28: =H25*Premissas!$C$6+H26*Premissas!$C$7 | I28: =I25*Premissas!$C$6+I26*Premissas!$C$7 | J28: =J25*Premissas!$C$6+J26*Premissas!$C$7 | ... AC28: =AC25*Premissas!$C$6+AC26*Premissas!$C$7
A29: Taxa de pagamento | B29: brl | C29: =C28*(Premissas!$C$8*Premissas!$C$9+(1-Premissas!$C$8)*Premissas!$C$10) | D29: =D28*(Premissas!$C$8*Premissas!$C$9+(1-Premissas!$C$8)*Premissas!$C$10) | E29: =E28*(Premissas!$C$8*Premissas!$C$9+(1-Premissas!$C$8)*Premissas!$C$10) | F29: =F28*(Premissas!$C$8*Premissas!$C$9+(1-Premissas!$C$8)*Premissas!$C$10) | G29: =G28*(Premissas!$C$8*Premissas!$C$9+(1-Premissas!$C$8)*Premissas!$C$10) | H29: =H28*(Premissas!$C$8*Premissas!$C$9+(1-Premissas!$C$8)*Premissas!$C$10) | I29: =I28*(Premissas!$C$8*Premissas!$C$9+(1-Premissas!$C$8)*Premissas!$C$10) | J29: =J28*(Premissas!$C$8*Premissas!$C$9+(1-Premissas!$C$8)*Premissas!$C$10) | ... AC29: =AC28*(Premissas!$C$8*Premissas!$C$9+(1-Premissas!$C$8)*Premissas!$C$10)
A30: Simples Nacional | B30: brl | C30: =C28*Premissas!$C$11 | D30: =D28*Premissas!$C$11 | E30: =E28*Premissas!$C$11 | F30: =F28*Premissas!$C$11 | G30: =G28*Premissas!$C$11 | H30: =H28*Premissas!$C$11 | I30: =I28*Premissas!$C$11 | J30: =J28*Premissas!$C$11 | ... AC30: =AC28*Premissas!$C$11
A31: Receita líquida | B31: brl | C31: =C28-C29-C30 | D31: =D28-D29-D30 | E31: =E28-E29-E30 | F31: =F28-F29-F30 | G31: =G28-G29-G30 | H31: =H28-H29-H30 | I31: =I28-I29-I30 | J31: =J28-J29-J30 | ... AC31: =AC28-AC29-AC30
A32: Custos em dinheiro
A33: Supabase | B33: brl | C33: =(Premissas!$C$12+IF(C17>Premissas!$C$29,Premissas!$C$30,IF(C17>Premissas!$C$27,Premissas!$C$28,IF(C17>Premissas!$C$25,Premissas!$C$26,0))))*Premissas!$C$5 | D33: =(Premissas!$C$12+IF(D17>Premissas!$C$29,Premissas!$C$30,IF(D17>Premissas!$C$27,Premissas!$C$28,IF(D17>Premissas!$C$25,Premissas!$C$26,0))))*Premissas!$C$5 | E33: =(Premissas!$C$12+IF(E17>Premissas!$C$29,Premissas!$C$30,IF(E17>Premissas!$C$27,Premissas!$C$28,IF(E17>Premissas!$C$25,Premissas!$C$26,0))))*Premissas!$C$5 | F33: =(Premissas!$C$12+IF(F17>Premissas!$C$29,Premissas!$C$30,IF(F17>Premissas!$C$27,Premissas!$C$28,IF(F17>Premissas!$C$25,Premissas!$C$26,0))))*Premissas!$C$5 | G33: =(Premissas!$C$12+IF(G17>Premissas!$C$29,Premissas!$C$30,IF(G17>Premissas!$C$27,Premissas!$C$28,IF(G17>Premissas!$C$25,Premissas!$C$26,0))))*Premissas!$C$5 | H33: =(Premissas!$C$12+IF(H17>Premissas!$C$29,Premissas!$C$30,IF(H17>Premissas!$C$27,Premissas!$C$28,IF(H17>Premissas!$C$25,Premissas!$C$26,0))))*Premissas!$C$5 | I33: =(Premissas!$C$12+IF(I17>Premissas!$C$29,Premissas!$C$30,IF(I17>Premissas!$C$27,Premissas!$C$28,IF(I17>Premissas!$C$25,Premissas!$C$26,0))))*Premissas!$C$5 | J33: =(Premissas!$C$12+IF(J17>Premissas!$C$29,Premissas!$C$30,IF(J17>Premissas!$C$27,Premissas!$C$28,IF(J17>Premissas!$C$25,Premissas!$C$26,0))))*Premissas!$C$5 | ... AC33: =(Premissas!$C$12+IF(AC17>Premissas!$C$29,Premissas!$C$30,IF(AC17>Premissas!$C$27,Premissas!$C$28,IF(AC17>Premissas!$C$25,Premissas!$C$26,0))))*Premissas!$C$5
A34: Vercel | B34: brl | C34: =(Premissas!$C$13+MAX(0,C17*Premissas!$C$15-Premissas!$C$14))*Premissas!$C$5 | D34: =(Premissas!$C$13+MAX(0,D17*Premissas!$C$15-Premissas!$C$14))*Premissas!$C$5 | E34: =(Premissas!$C$13+MAX(0,E17*Premissas!$C$15-Premissas!$C$14))*Premissas!$C$5 | F34: =(Premissas!$C$13+MAX(0,F17*Premissas!$C$15-Premissas!$C$14))*Premissas!$C$5 | G34: =(Premissas!$C$13+MAX(0,G17*Premissas!$C$15-Premissas!$C$14))*Premissas!$C$5 | H34: =(Premissas!$C$13+MAX(0,H17*Premissas!$C$15-Premissas!$C$14))*Premissas!$C$5 | I34: =(Premissas!$C$13+MAX(0,I17*Premissas!$C$15-Premissas!$C$14))*Premissas!$C$5 | J34: =(Premissas!$C$13+MAX(0,J17*Premissas!$C$15-Premissas!$C$14))*Premissas!$C$5 | ... AC34: =(Premissas!$C$13+MAX(0,AC17*Premissas!$C$15-Premissas!$C$14))*Premissas!$C$5
A35: Contabilidade e INSS do pró-labore | B35: brl | C35: =Premissas!$C$16+Premissas!$C$17*Premissas!$C$18 | D35: =Premissas!$C$16+Premissas!$C$17*Premissas!$C$18 | E35: =Premissas!$C$16+Premissas!$C$17*Premissas!$C$18 | F35: =Premissas!$C$16+Premissas!$C$17*Premissas!$C$18 | G35: =Premissas!$C$16+Premissas!$C$17*Premissas!$C$18 | H35: =Premissas!$C$16+Premissas!$C$17*Premissas!$C$18 | I35: =Premissas!$C$16+Premissas!$C$17*Premissas!$C$18 | J35: =Premissas!$C$16+Premissas!$C$17*Premissas!$C$18 | ... AC35: =Premissas!$C$16+Premissas!$C$17*Premissas!$C$18
A36: Domínio e e-mail próprio | B36: brl | C36: =Premissas!$C$19+Premissas!$C$20 | D36: =Premissas!$C$19+Premissas!$C$20 | E36: =Premissas!$C$19+Premissas!$C$20 | F36: =Premissas!$C$19+Premissas!$C$20 | G36: =Premissas!$C$19+Premissas!$C$20 | H36: =Premissas!$C$19+Premissas!$C$20 | I36: =Premissas!$C$19+Premissas!$C$20 | J36: =Premissas!$C$19+Premissas!$C$20 | ... AC36: =Premissas!$C$19+Premissas!$C$20
A37: Resend e Sentry (quando passam do grátis) | B37: brl | C37: =(IF(C17>Premissas!$C$22,Premissas!$C$21,0)+IF(C17>Premissas!$C$24,Premissas!$C$23,0))*Premissas!$C$5 | D37: =(IF(D17>Premissas!$C$22,Premissas!$C$21,0)+IF(D17>Premissas!$C$24,Premissas!$C$23,0))*Premissas!$C$5 | E37: =(IF(E17>Premissas!$C$22,Premissas!$C$21,0)+IF(E17>Premissas!$C$24,Premissas!$C$23,0))*Premissas!$C$5 | F37: =(IF(F17>Premissas!$C$22,Premissas!$C$21,0)+IF(F17>Premissas!$C$24,Premissas!$C$23,0))*Premissas!$C$5 | G37: =(IF(G17>Premissas!$C$22,Premissas!$C$21,0)+IF(G17>Premissas!$C$24,Premissas!$C$23,0))*Premissas!$C$5 | H37: =(IF(H17>Premissas!$C$22,Premissas!$C$21,0)+IF(H17>Premissas!$C$24,Premissas!$C$23,0))*Premissas!$C$5 | I37: =(IF(I17>Premissas!$C$22,Premissas!$C$21,0)+IF(I17>Premissas!$C$24,Premissas!$C$23,0))*Premissas!$C$5 | J37: =(IF(J17>Premissas!$C$22,Premissas!$C$21,0)+IF(J17>Premissas!$C$24,Premissas!$C$23,0))*Premissas!$C$5 | ... AC37: =(IF(AC17>Premissas!$C$22,Premissas!$C$21,0)+IF(AC17>Premissas!$C$24,Premissas!$C$23,0))*Premissas!$C$5
A38: Rua: transporte | B38: brl | C38: =C7*Premissas!$C$31 | D38: =D7*Premissas!$C$31 | E38: =E7*Premissas!$C$31 | F38: =F7*Premissas!$C$31 | G38: =G7*Premissas!$C$31 | H38: =H7*Premissas!$C$31 | I38: =I7*Premissas!$C$31 | J38: =J7*Premissas!$C$31 | ... AC38: =AC7*Premissas!$C$31
A39: Conteúdo e material | B39: brl | C39: =Premissas!$C$32 | D39: =Premissas!$C$32 | E39: =Premissas!$C$32 | F39: =Premissas!$C$32 | G39: =Premissas!$C$32 | H39: =Premissas!$C$32 | I39: =Premissas!$C$32 | J39: =Premissas!$C$32 | ... AC39: =Premissas!$C$32
A40: Total de custos | B40: brl | C40: =SUM(C33:C39) | D40: =SUM(D33:D39) | E40: =SUM(E33:E39) | F40: =SUM(F33:F39) | G40: =SUM(G33:G39) | H40: =SUM(H33:H39) | I40: =SUM(I33:I39) | J40: =SUM(J33:J39) | ... AC40: =SUM(AC33:AC39)
A41: Resultado operacional | B41: brl | C41: =C31-C40 | D41: =D31-D40 | E41: =E31-E40 | F41: =F31-F40 | G41: =G31-G40 | H41: =H31-H40 | I41: =I31-I40 | J41: =J31-J40 | ... AC41: =AC31-AC40
...

Sheet Base
A1: CICLO · Projeção mês a mês · cenário Base
A2: Tudo aqui é fórmula. Mude as premissas na aba Premissas e no Calendário.
A4: Linha | B4: Unid. | C4: Out/26 | D4: Nov/26 | E4: Dez/26 | F4: Jan/27 | G4: Fev/27 | H4: Mar/27 | I4: Abr/27 | J4: Mai/27 | K4: Jun/27 | L4: Jul/27 | M4: Ago/27 | N4: Set/27 | O4: Out/27 | P4: Nov/27 | Q4: Dez/27 | R4: Jan/28 | S4: Fev/28 | T4: Mar/28 | U4: Abr/28 | V4: Mai/28 | W4: Jun/28 | X4: Jul/28 | Y4: Ago/28 | Z4: Set/28 | AA4: Out/28 | AB4: Nov/28 | AC4: Dez/28
A5: Prospecção e contas
A6: Fase | C6: =Calendario!C6 | D6: =Calendario!D6 | E6: =Calendario!E6 | F6: =Calendario!F6 | G6: =Calendario!G6 | H6: =Calendario!H6 | I6: =Calendario!I6 | J6: =Calendario!J6 | ... AC6: =Calendario!AC6
A7: Dias de rua | B7: dias | C7: =Calendario!C7 | D7: =Calendario!D7 | E7: =Calendario!E7 | F7: =Calendario!F7 | G7: =Calendario!G7 | H7: =Calendario!H7 | I7: =Calendario!I7 | J7: =Calendario!J7 | ... AC7: =Calendario!AC7
A8: Abordagens | B8: n | C8: =C7*Premissas!$C$44 | D8: =D7*Premissas!$C$44 | E8: =E7*Premissas!$C$44 | F8: =F7*Premissas!$C$44 | G8: =G7*Premissas!$C$44 | H8: =H7*Premissas!$C$44 | I8: =I7*Premissas!$C$44 | J8: =J7*Premissas!$C$44 | ... AC8: =AC7*Premissas!$C$44
A9: Conversas de verdade | B9: n | C9: =C8*Premissas!$C$47 | D9: =D8*Premissas!$C$47 | E9: =E8*Premissas!$C$47 | F9: =F8*Premissas!$C$47 | G9: =G8*Premissas!$C$47 | H9: =H8*Premissas!$C$47 | I9: =I8*Premissas!$C$47 | J9: =J8*Premissas!$C$47 | ... AC9: =AC8*Premissas!$C$47
A10: Contas por prospecção | B10: n | C10: =C9*Premissas!$C$48 | D10: =D9*Premissas!$C$48 | E10: =E9*Premissas!$C$48 | F10: =F9*Premissas!$C$48 | G10: =G9*Premissas!$C$48 | H10: =H9*Premissas!$C$48 | I10: =I9*Premissas!$C$48 | J10: =J9*Premissas!$C$48 | ... AC10: =AC9*Premissas!$C$48
A11: Contas por indicação, parceiros e conteúdo | B11: n | C11: =0*Premissas!$C$53+Calendario!C11*Premissas!$C$54 | D11: =C23*Premissas!$C$53+Calendario!D11*Premissas!$C$54 | E11: =D23*Premissas!$C$53+Calendario!E11*Premissas!$C$54 | F11: =E23*Premissas!$C$53+Calendario!F11*Premissas!$C$54 | G11: =F23*Premissas!$C$53+Calendario!G11*Premissas!$C$54 | H11: =G23*Premissas!$C$53+Calendario!H11*Premissas!$C$54 | I11: =H23*Premissas!$C$53+Calendario!I11*Premissas!$C$54 | J11: =I23*Premissas!$C$53+Calendario!J11*Premissas!$C$54 | K11: =J23*Premissas!$C$53+Calendario!K11*Premissas!$C$54 | ... AC11: =AB23*Premissas!$C$53+Calendario!AC11*Premissas!$C$54
A12: Contas do alpha (convidadas) | B12: n | C12: =Calendario!C10*Premissas!$C$41 | D12: =Calendario!D10*Premissas!$C$41 | E12: =Calendario!E10*Premissas!$C$41 | F12: =Calendario!F10*Premissas!$C$41 | G12: =Calendario!G10*Premissas!$C$41 | H12: =Calendario!H10*Premissas!$C$41 | I12: =Calendario!I10*Premissas!$C$41 | J12: =Calendario!J10*Premissas!$C$41 | ... AC12: =Calendario!AC10*Premissas!$C$41
A13: Demanda total de contas | B13: n | C13: =C10+C11+C12 | D13: =D10+D11+D12 | E13: =E10+E11+E12 | F13: =F10+F11+F12 | G13: =G10+G11+G12 | H13: =H10+H11+H12 | I13: =I10+I11+I12 | J13: =J10+J11+J12 | ... AC13: =AC10+AC11+AC12
A14: Capacidade de atender | B14: n | C14: =IF(Calendario!C8=0,MAX(0,Premissas!$C$42-0),Premissas!$C$43) | D14: =IF(Calendario!D8=0,MAX(0,Premissas!$C$42-C17),Premissas!$C$43) | E14: =IF(Calendario!E8=0,MAX(0,Premissas!$C$42-D17),Premissas!$C$43) | F14: =IF(Calendario!F8=0,MAX(0,Premissas!$C$42-E17),Premissas!$C$43) | G14: =IF(Calendario!G8=0,MAX(0,Premissas!$C$42-F17),Premissas!$C$43) | H14: =IF(Calendario!H8=0,MAX(0,Premissas!$C$42-G17),Premissas!$C$43) | I14: =IF(Calendario!I8=0,MAX(0,Premissas!$C$42-H17),Premissas!$C$43) | J14: =IF(Calendario!J8=0,MAX(0,Premissas!$C$42-I17),Premissas!$C$43) | K14: =IF(Calendario!K8=0,MAX(0,Premissas!$C$42-J17),Premissas!$C$43) | ... AC14: =IF(Calendario!AC8=0,MAX(0,Premissas!$C$42-AB17),Premissas!$C$43)
A15: Contas criadas | B15: n | C15: =MIN(C13,C14) | D15: =MIN(D13,D14) | E15: =MIN(E13,E14) | F15: =MIN(F13,F14) | G15: =MIN(G13,G14) | H15: =MIN(H13,H14) | I15: =MIN(I13,I14) | J15: =MIN(J13,J14) | ... AC15: =MIN(AC13,AC14)
A16: Fila de espera gerada | B16: n | C16: =C13-C15 | D16: =D13-D15 | E16: =E13-E15 | F16: =F13-F15 | G16: =G13-G15 | H16: =H13-H15 | I16: =I13-I15 | J16: =J13-J15 | ... AC16: =AC13-AC15
A17: Contas acumuladas | B17: n | C17: =0+C15 | D17: =C17+D15 | E17: =D17+E15 | F17: =E17+F15 | G17: =F17+G15 | H17: =G17+H15 | I17: =H17+I15 | J17: =I17+J15 | K17: =J17+K15 | ... AC17: =AB17+AC15
A18: Contas ativas novas | B18: n | C18: =C15*Premissas!$C$49 | D18: =D15*Premissas!$C$49 | E18: =E15*Premissas!$C$49 | F18: =F15*Premissas!$C$49 | G18: =G15*Premissas!$C$49 | H18: =H15*Premissas!$C$49 | I18: =I15*Premissas!$C$49 | J18: =J15*Premissas!$C$49 | ... AC18: =AC15*Premissas!$C$49
A19: Pagantes
A20: Pagantes no início | B20: n | C20: =0 | D20: =C23 | E20: =D23 | F20: =E23 | G20: =F23 | H20: =G23 | I20: =H23 | J20: =I23 | K20: =J23 | ... AC20: =AB23
A21: Novos pagantes | B21: n1 | C21: =Calendario!C9*0*Premissas!$C$50+(Calendario!C8-Calendario!C9)*0*Premissas!$C$50 | D21: =Calendario!D9*C17*Premissas!$C$50+(Calendario!D8-Calendario!D9)*C15*Premissas!$C$50 | E21: =Calendario!E9*D17*Premissas!$C$50+(Calendario!E8-Calendario!E9)*D15*Premissas!$C$50 | F21: =Calendario!F9*E17*Premissas!$C$50+(Calendario!F8-Calendario!F9)*E15*Premissas!$C$50 | G21: =Calendario!G9*F17*Premissas!$C$50+(Calendario!G8-Calendario!G9)*F15*Premissas!$C$50 | H21: =Calendario!H9*G17*Premissas!$C$50+(Calendario!H8-Calendario!H9)*G15*Premissas!$C$50 | I21: =Calendario!I9*H17*Premissas!$C$50+(Calendario!I8-Calendario!I9)*H15*Premissas!$C$50 | J21: =Calendario!J9*I17*Premissas!$C$50+(Calendario!J8-Calendario!J9)*I15*Premissas!$C$50 | K21: =Calendario!K9*J17*Premissas!$C$50+(Calendario!K8-Calendario!K9)*J15*Premissas!$C$50 | ... AC21: =Calendario!AC9*AB17*Premissas!$C$50+(Calendario!AC8-Calendario!AC9)*AB15*Premissas!$C$50
A22: Cancelamentos | B22: n1 | C22: =C20*Premissas!$C$51 | D22: =D20*Premissas!$C$51 | E22: =E20*Premissas!$C$51 | F22: =F20*Premissas!$C$51 | G22: =G20*Premissas!$C$51 | H22: =H20*Premissas!$C$51 | I22: =I20*Premissas!$C$51 | J22: =J20*Premissas!$C$51 | ... AC22: =AC20*Premissas!$C$51
A23: Pagantes no fim | B23: n1 | C23: =C20+C21-C22 | D23: =D20+D21-D22 | E23: =E20+E21-E22 | F23: =F20+F21-F22 | G23: =G20+G21-G22 | H23: =H20+H21-H22 | I23: =I20+I21-I22 | J23: =J20+J21-J22 | ... AC23: =AC20+AC21-AC22
A24: Pagantes médios | B24: n1 | C24: =(C20+C23)/2 | D24: =(D20+D23)/2 | E24: =(E20+E23)/2 | F24: =(F20+F23)/2 | G24: =(G20+G23)/2 | H24: =(H20+H23)/2 | I24: =(I20+I23)/2 | J24: =(J20+J23)/2 | ... AC24: =(AC20+AC23)/2
A25: no Solo | B25: n1 | C25: =C24*Premissas!$C$52 | D25: =D24*Premissas!$C$52 | E25: =E24*Premissas!$C$52 | F25: =F24*Premissas!$C$52 | G25: =G24*Premissas!$C$52 | H25: =H24*Premissas!$C$52 | I25: =I24*Premissas!$C$52 | J25: =J24*Premissas!$C$52 | ... AC25: =AC24*Premissas!$C$52
A26: no Equipe | B26: n1 | C26: =C24-C25 | D26: =D24-D25 | E26: =E24-E25 | F26: =F24-F25 | G26: =G24-G25 | H26: =H24-H25 | I26: =I24-I25 | J26: =J24-J25 | ... AC26: =AC24-AC25
A27: Receita
A28: Receita bruta | B28: brl | C28: =C25*Premissas!$C$6+C26*Premissas!$C$7 | D28: =D25*Premissas!$C$6+D26*Premissas!$C$7 | E28: =E25*Premissas!$C$6+E26*Premissas!$C$7 | F28: =F25*Premissas!$C$6+F26*Premissas!$C$7 | G28: =G25*Premissas!$C$6+G26*Premissas!$C$7 | H28: =H25*Premissas!$C$6+H26*Premissas!$C$7 | I28: =I25*Premissas!$C$6+I26*Premissas!$C$7 | J28: =J25*Premissas!$C$6+J26*Premissas!$C$7 | ... AC28: =AC25*Premissas!$C$6+AC26*Premissas!$C$7
A29: Taxa de pagamento | B29: brl | C29: =C28*(Premissas!$C$8*Premissas!$C$9+(1-Premissas!$C$8)*Premissas!$C$10) | D29: =D28*(Premissas!$C$8*Premissas!$C$9+(1-Premissas!$C$8)*Premissas!$C$10) | E29: =E28*(Premissas!$C$8*Premissas!$C$9+(1-Premissas!$C$8)*Premissas!$C$10) | F29: =F28*(Premissas!$C$8*Premissas!$C$9+(1-Premissas!$C$8)*Premissas!$C$10) | G29: =G28*(Premissas!$C$8*Premissas!$C$9+(1-Premissas!$C$8)*Premissas!$C$10) | H29: =H28*(Premissas!$C$8*Premissas!$C$9+(1-Premissas!$C$8)*Premissas!$C$10) | I29: =I28*(Premissas!$C$8*Premissas!$C$9+(1-Premissas!$C$8)*Premissas!$C$10) | J29: =J28*(Premissas!$C$8*Premissas!$C$9+(1-Premissas!$C$8)*Premissas!$C$10) | ... AC29: =AC28*(Premissas!$C$8*Premissas!$C$9+(1-Premissas!$C$8)*Premissas!$C$10)
A30: Simples Nacional | B30: brl | C30: =C28*Premissas!$C$11 | D30: =D28*Premissas!$C$11 | E30: =E28*Premissas!$C$11 | F30: =F28*Premissas!$C$11 | G30: =G28*Premissas!$C$11 | H30: =H28*Premissas!$C$11 | I30: =I28*Premissas!$C$11 | J30: =J28*Premissas!$C$11 | ... AC30: =AC28*Premissas!$C$11
A31: Receita líquida | B31: brl | C31: =C28-C29-C30 | D31: =D28-D29-D30 | E31: =E28-E29-E30 | F31: =F28-F29-F30 | G31: =G28-G29-G30 | H31: =H28-H29-H30 | I31: =I28-I29-I30 | J31: =J28-J29-J30 | ... AC31: =AC28-AC29-AC30
A32: Custos em dinheiro
A33: Supabase | B33: brl | C33: =(Premissas!$C$12+IF(C17>Premissas!$C$29,Premissas!$C$30,IF(C17>Premissas!$C$27,Premissas!$C$28,IF(C17>Premissas!$C$25,Premissas!$C$26,0))))*Premissas!$C$5 | D33: =(Premissas!$C$12+IF(D17>Premissas!$C$29,Premissas!$C$30,IF(D17>Premissas!$C$27,Premissas!$C$28,IF(D17>Premissas!$C$25,Premissas!$C$26,0))))*Premissas!$C$5 | E33: =(Premissas!$C$12+IF(E17>Premissas!$C$29,Premissas!$C$30,IF(E17>Premissas!$C$27,Premissas!$C$28,IF(E17>Premissas!$C$25,Premissas!$C$26,0))))*Premissas!$C$5 | F33: =(Premissas!$C$12+IF(F17>Premissas!$C$29,Premissas!$C$30,IF(F17>Premissas!$C$27,Premissas!$C$28,IF(F17>Premissas!$C$25,Premissas!$C$26,0))))*Premissas!$C$5 | G33: =(Premissas!$C$12+IF(G17>Premissas!$C$29,Premissas!$C$30,IF(G17>Premissas!$C$27,Premissas!$C$28,IF(G17>Premissas!$C$25,Premissas!$C$26,0))))*Premissas!$C$5 | H33: =(Premissas!$C$12+IF(H17>Premissas!$C$29,Premissas!$C$30,IF(H17>Premissas!$C$27,Premissas!$C$28,IF(H17>Premissas!$C$25,Premissas!$C$26,0))))*Premissas!$C$5 | I33: =(Premissas!$C$12+IF(I17>Premissas!$C$29,Premissas!$C$30,IF(I17>Premissas!$C$27,Premissas!$C$28,IF(I17>Premissas!$C$25,Premissas!$C$26,0))))*Premissas!$C$5 | J33: =(Premissas!$C$12+IF(J17>Premissas!$C$29,Premissas!$C$30,IF(J17>Premissas!$C$27,Premissas!$C$28,IF(J17>Premissas!$C$25,Premissas!$C$26,0))))*Premissas!$C$5 | ... AC33: =(Premissas!$C$12+IF(AC17>Premissas!$C$29,Premissas!$C$30,IF(AC17>Premissas!$C$27,Premissas!$C$28,IF(AC17>Premissas!$C$25,Premissas!$C$26,0))))*Premissas!$C$5
A34: Vercel | B34: brl | C34: =(Premissas!$C$13+MAX(0,C17*Premissas!$C$15-Premissas!$C$14))*Premissas!$C$5 | D34: =(Premissas!$C$13+MAX(0,D17*Premissas!$C$15-Premissas!$C$14))*Premissas!$C$5 | E34: =(Premissas!$C$13+MAX(0,E17*Premissas!$C$15-Premissas!$C$14))*Premissas!$C$5 | F34: =(Premissas!$C$13+MAX(0,F17*Premissas!$C$15-Premissas!$C$14))*Premissas!$C$5 | G34: =(Premissas!$C$13+MAX(0,G17*Premissas!$C$15-Premissas!$C$14))*Premissas!$C$5 | H34: =(Premissas!$C$13+MAX(0,H17*Premissas!$C$15-Premissas!$C$14))*Premissas!$C$5 | I34: =(Premissas!$C$13+MAX(0,I17*Premissas!$C$15-Premissas!$C$14))*Premissas!$C$5 | J34: =(Premissas!$C$13+MAX(0,J17*Premissas!$C$15-Premissas!$C$14))*Premissas!$C$5 | ... AC34: =(Premissas!$C$13+MAX(0,AC17*Premissas!$C$15-Premissas!$C$14))*Premissas!$C$5
A35: Contabilidade e INSS do pró-labore | B35: brl | C35: =Premissas!$C$16+Premissas!$C$17*Premissas!$C$18 | D35: =Premissas!$C$16+Premissas!$C$17*Premissas!$C$18 | E35: =Premissas!$C$16+Premissas!$C$17*Premissas!$C$18 | F35: =Premissas!$C$16+Premissas!$C$17*Premissas!$C$18 | G35: =Premissas!$C$16+Premissas!$C$17*Premissas!$C$18 | H35: =Premissas!$C$16+Premissas!$C$17*Premissas!$C$18 | I35: =Premissas!$C$16+Premissas!$C$17*Premissas!$C$18 | J35: =Premissas!$C$16+Premissas!$C$17*Premissas!$C$18 | ... AC35: =Premissas!$C$16+Premissas!$C$17*Premissas!$C$18
A36: Domínio e e-mail próprio | B36: brl | C36: =Premissas!$C$19+Premissas!$C$20 | D36: =Premissas!$C$19+Premissas!$C$20 | E36: =Premissas!$C$19+Premissas!$C$20 | F36: =Premissas!$C$19+Premissas!$C$20 | G36: =Premissas!$C$19+Premissas!$C$20 | H36: =Premissas!$C$19+Premissas!$C$20 | I36: =Premissas!$C$19+Premissas!$C$20 | J36: =Premissas!$C$19+Premissas!$C$20 | ... AC36: =Premissas!$C$19+Premissas!$C$20
A37: Resend e Sentry (quando passam do grátis) | B37: brl | C37: =(IF(C17>Premissas!$C$22,Premissas!$C$21,0)+IF(C17>Premissas!$C$24,Premissas!$C$23,0))*Premissas!$C$5 | D37: =(IF(D17>Premissas!$C$22,Premissas!$C$21,0)+IF(D17>Premissas!$C$24,Premissas!$C$23,0))*Premissas!$C$5 | E37: =(IF(E17>Premissas!$C$22,Premissas!$C$21,0)+IF(E17>Premissas!$C$24,Premissas!$C$23,0))*Premissas!$C$5 | F37: =(IF(F17>Premissas!$C$22,Premissas!$C$21,0)+IF(F17>Premissas!$C$24,Premissas!$C$23,0))*Premissas!$C$5 | G37: =(IF(G17>Premissas!$C$22,Premissas!$C$21,0)+IF(G17>Premissas!$C$24,Premissas!$C$23,0))*Premissas!$C$5 | H37: =(IF(H17>Premissas!$C$22,Premissas!$C$21,0)+IF(H17>Premissas!$C$24,Premissas!$C$23,0))*Premissas!$C$5 | I37: =(IF(I17>Premissas!$C$22,Premissas!$C$21,0)+IF(I17>Premissas!$C$24,Premissas!$C$23,0))*Premissas!$C$5 | J37: =(IF(J17>Premissas!$C$22,Premissas!$C$21,0)+IF(J17>Premissas!$C$24,Premissas!$C$23,0))*Premissas!$C$5 | ... AC37: =(IF(AC17>Premissas!$C$22,Premissas!$C$21,0)+IF(AC17>Premissas!$C$24,Premissas!$C$23,0))*Premissas!$C$5
A38: Rua: transporte | B38: brl | C38: =C7*Premissas!$C$31 | D38: =D7*Premissas!$C$31 | E38: =E7*Premissas!$C$31 | F38: =F7*Premissas!$C$31 | G38: =G7*Premissas!$C$31 | H38: =H7*Premissas!$C$31 | I38: =I7*Premissas!$C$31 | J38: =J7*Premissas!$C$31 | ... AC38: =AC7*Premissas!$C$31
A39: Conteúdo e material | B39: brl | C39: =Premissas!$C$32 | D39: =Premissas!$C$32 | E39: =Premissas!$C$32 | F39: =Premissas!$C$32 | G39: =Premissas!$C$32 | H39: =Premissas!$C$32 | I39: =Premissas!$C$32 | J39: =Premissas!$C$32 | ... AC39: =Premissas!$C$32
A40: Total de custos | B40: brl | C40: =SUM(C33:C39) | D40: =SUM(D33:D39) | E40: =SUM(E33:E39) | F40: =SUM(F33:F39) | G40: =SUM(G33:G39) | H40: =SUM(H33:H39) | I40: =SUM(I33:I39) | J40: =SUM(J33:J39) | ... AC40: =SUM(AC33:AC39)
A41: Resultado operacional | B41: brl | C41: =C31-C40 | D41: =D31-D40 | E41: =E31-E40 | F41: =F31-F40 | G41: =G31-G40 | H41: =H31-H40 | I41: =I31-I40 | J41: =J31-J40 | ... AC41: =AC31-AC40
...

Sheet Otimista
A1: CICLO · Projeção mês a mês · cenário Otimista
A2: Tudo aqui é fórmula. Mude as premissas na aba Premissas e no Calendário.
A4: Linha | B4: Unid. | C4: Out/26 | D4: Nov/26 | E4: Dez/26 | F4: Jan/27 | G4: Fev/27 | H4: Mar/27 | I4: Abr/27 | J4: Mai/27 | K4: Jun/27 | L4: Jul/27 | M4: Ago/27 | N4: Set/27 | O4: Out/27 | P4: Nov/27 | Q4: Dez/27 | R4: Jan/28 | S4: Fev/28 | T4: Mar/28 | U4: Abr/28 | V4: Mai/28 | W4: Jun/28 | X4: Jul/28 | Y4: Ago/28 | Z4: Set/28 | AA4: Out/28 | AB4: Nov/28 | AC4: Dez/28
A5: Prospecção e contas
A6: Fase | C6: =Calendario!C6 | D6: =Calendario!D6 | E6: =Calendario!E6 | F6: =Calendario!F6 | G6: =Calendario!G6 | H6: =Calendario!H6 | I6: =Calendario!I6 | J6: =Calendario!J6 | ... AC6: =Calendario!AC6
A7: Dias de rua | B7: dias | C7: =Calendario!C7 | D7: =Calendario!D7 | E7: =Calendario!E7 | F7: =Calendario!F7 | G7: =Calendario!G7 | H7: =Calendario!H7 | I7: =Calendario!I7 | J7: =Calendario!J7 | ... AC7: =Calendario!AC7
A8: Abordagens | B8: n | C8: =C7*Premissas!$C$44 | D8: =D7*Premissas!$C$44 | E8: =E7*Premissas!$C$44 | F8: =F7*Premissas!$C$44 | G8: =G7*Premissas!$C$44 | H8: =H7*Premissas!$C$44 | I8: =I7*Premissas!$C$44 | J8: =J7*Premissas!$C$44 | ... AC8: =AC7*Premissas!$C$44
A9: Conversas de verdade | B9: n | C9: =C8*Premissas!$D$47 | D9: =D8*Premissas!$D$47 | E9: =E8*Premissas!$D$47 | F9: =F8*Premissas!$D$47 | G9: =G8*Premissas!$D$47 | H9: =H8*Premissas!$D$47 | I9: =I8*Premissas!$D$47 | J9: =J8*Premissas!$D$47 | ... AC9: =AC8*Premissas!$D$47
A10: Contas por prospecção | B10: n | C10: =C9*Premissas!$D$48 | D10: =D9*Premissas!$D$48 | E10: =E9*Premissas!$D$48 | F10: =F9*Premissas!$D$48 | G10: =G9*Premissas!$D$48 | H10: =H9*Premissas!$D$48 | I10: =I9*Premissas!$D$48 | J10: =J9*Premissas!$D$48 | ... AC10: =AC9*Premissas!$D$48
A11: Contas por indicação, parceiros e conteúdo | B11: n | C11: =0*Premissas!$D$53+Calendario!C11*Premissas!$D$54 | D11: =C23*Premissas!$D$53+Calendario!D11*Premissas!$D$54 | E11: =D23*Premissas!$D$53+Calendario!E11*Premissas!$D$54 | F11: =E23*Premissas!$D$53+Calendario!F11*Premissas!$D$54 | G11: =F23*Premissas!$D$53+Calendario!G11*Premissas!$D$54 | H11: =G23*Premissas!$D$53+Calendario!H11*Premissas!$D$54 | I11: =H23*Premissas!$D$53+Calendario!I11*Premissas!$D$54 | J11: =I23*Premissas!$D$53+Calendario!J11*Premissas!$D$54 | K11: =J23*Premissas!$D$53+Calendario!K11*Premissas!$D$54 | ... AC11: =AB23*Premissas!$D$53+Calendario!AC11*Premissas!$D$54
A12: Contas do alpha (convidadas) | B12: n | C12: =Calendario!C10*Premissas!$C$41 | D12: =Calendario!D10*Premissas!$C$41 | E12: =Calendario!E10*Premissas!$C$41 | F12: =Calendario!F10*Premissas!$C$41 | G12: =Calendario!G10*Premissas!$C$41 | H12: =Calendario!H10*Premissas!$C$41 | I12: =Calendario!I10*Premissas!$C$41 | J12: =Calendario!J10*Premissas!$C$41 | ... AC12: =Calendario!AC10*Premissas!$C$41
A13: Demanda total de contas | B13: n | C13: =C10+C11+C12 | D13: =D10+D11+D12 | E13: =E10+E11+E12 | F13: =F10+F11+F12 | G13: =G10+G11+G12 | H13: =H10+H11+H12 | I13: =I10+I11+I12 | J13: =J10+J11+J12 | ... AC13: =AC10+AC11+AC12
A14: Capacidade de atender | B14: n | C14: =IF(Calendario!C8=0,MAX(0,Premissas!$C$42-0),Premissas!$C$43) | D14: =IF(Calendario!D8=0,MAX(0,Premissas!$C$42-C17),Premissas!$C$43) | E14: =IF(Calendario!E8=0,MAX(0,Premissas!$C$42-D17),Premissas!$C$43) | F14: =IF(Calendario!F8=0,MAX(0,Premissas!$C$42-E17),Premissas!$C$43) | G14: =IF(Calendario!G8=0,MAX(0,Premissas!$C$42-F17),Premissas!$C$43) | H14: =IF(Calendario!H8=0,MAX(0,Premissas!$C$42-G17),Premissas!$C$43) | I14: =IF(Calendario!I8=0,MAX(0,Premissas!$C$42-H17),Premissas!$C$43) | J14: =IF(Calendario!J8=0,MAX(0,Premissas!$C$42-I17),Premissas!$C$43) | K14: =IF(Calendario!K8=0,MAX(0,Premissas!$C$42-J17),Premissas!$C$43) | ... AC14: =IF(Calendario!AC8=0,MAX(0,Premissas!$C$42-AB17),Premissas!$C$43)
A15: Contas criadas | B15: n | C15: =MIN(C13,C14) | D15: =MIN(D13,D14) | E15: =MIN(E13,E14) | F15: =MIN(F13,F14) | G15: =MIN(G13,G14) | H15: =MIN(H13,H14) | I15: =MIN(I13,I14) | J15: =MIN(J13,J14) | ... AC15: =MIN(AC13,AC14)
A16: Fila de espera gerada | B16: n | C16: =C13-C15 | D16: =D13-D15 | E16: =E13-E15 | F16: =F13-F15 | G16: =G13-G15 | H16: =H13-H15 | I16: =I13-I15 | J16: =J13-J15 | ... AC16: =AC13-AC15
A17: Contas acumuladas | B17: n | C17: =0+C15 | D17: =C17+D15 | E17: =D17+E15 | F17: =E17+F15 | G17: =F17+G15 | H17: =G17+H15 | I17: =H17+I15 | J17: =I17+J15 | K17: =J17+K15 | ... AC17: =AB17+AC15
A18: Contas ativas novas | B18: n | C18: =C15*Premissas!$D$49 | D18: =D15*Premissas!$D$49 | E18: =E15*Premissas!$D$49 | F18: =F15*Premissas!$D$49 | G18: =G15*Premissas!$D$49 | H18: =H15*Premissas!$D$49 | I18: =I15*Premissas!$D$49 | J18: =J15*Premissas!$D$49 | ... AC18: =AC15*Premissas!$D$49
A19: Pagantes
A20: Pagantes no início | B20: n | C20: =0 | D20: =C23 | E20: =D23 | F20: =E23 | G20: =F23 | H20: =G23 | I20: =H23 | J20: =I23 | K20: =J23 | ... AC20: =AB23
A21: Novos pagantes | B21: n1 | C21: =Calendario!C9*0*Premissas!$D$50+(Calendario!C8-Calendario!C9)*0*Premissas!$D$50 | D21: =Calendario!D9*C17*Premissas!$D$50+(Calendario!D8-Calendario!D9)*C15*Premissas!$D$50 | E21: =Calendario!E9*D17*Premissas!$D$50+(Calendario!E8-Calendario!E9)*D15*Premissas!$D$50 | F21: =Calendario!F9*E17*Premissas!$D$50+(Calendario!F8-Calendario!F9)*E15*Premissas!$D$50 | G21: =Calendario!G9*F17*Premissas!$D$50+(Calendario!G8-Calendario!G9)*F15*Premissas!$D$50 | H21: =Calendario!H9*G17*Premissas!$D$50+(Calendario!H8-Calendario!H9)*G15*Premissas!$D$50 | I21: =Calendario!I9*H17*Premissas!$D$50+(Calendario!I8-Calendario!I9)*H15*Premissas!$D$50 | J21: =Calendario!J9*I17*Premissas!$D$50+(Calendario!J8-Calendario!J9)*I15*Premissas!$D$50 | K21: =Calendario!K9*J17*Premissas!$D$50+(Calendario!K8-Calendario!K9)*J15*Premissas!$D$50 | ... AC21: =Calendario!AC9*AB17*Premissas!$D$50+(Calendario!AC8-Calendario!AC9)*AB15*Premissas!$D$50
A22: Cancelamentos | B22: n1 | C22: =C20*Premissas!$D$51 | D22: =D20*Premissas!$D$51 | E22: =E20*Premissas!$D$51 | F22: =F20*Premissas!$D$51 | G22: =G20*Premissas!$D$51 | H22: =H20*Premissas!$D$51 | I22: =I20*Premissas!$D$51 | J22: =J20*Premissas!$D$51 | ... AC22: =AC20*Premissas!$D$51
A23: Pagantes no fim | B23: n1 | C23: =C20+C21-C22 | D23: =D20+D21-D22 | E23: =E20+E21-E22 | F23: =F20+F21-F22 | G23: =G20+G21-G22 | H23: =H20+H21-H22 | I23: =I20+I21-I22 | J23: =J20+J21-J22 | ... AC23: =AC20+AC21-AC22
A24: Pagantes médios | B24: n1 | C24: =(C20+C23)/2 | D24: =(D20+D23)/2 | E24: =(E20+E23)/2 | F24: =(F20+F23)/2 | G24: =(G20+G23)/2 | H24: =(H20+H23)/2 | I24: =(I20+I23)/2 | J24: =(J20+J23)/2 | ... AC24: =(AC20+AC23)/2
A25: no Solo | B25: n1 | C25: =C24*Premissas!$D$52 | D25: =D24*Premissas!$D$52 | E25: =E24*Premissas!$D$52 | F25: =F24*Premissas!$D$52 | G25: =G24*Premissas!$D$52 | H25: =H24*Premissas!$D$52 | I25: =I24*Premissas!$D$52 | J25: =J24*Premissas!$D$52 | ... AC25: =AC24*Premissas!$D$52
A26: no Equipe | B26: n1 | C26: =C24-C25 | D26: =D24-D25 | E26: =E24-E25 | F26: =F24-F25 | G26: =G24-G25 | H26: =H24-H25 | I26: =I24-I25 | J26: =J24-J25 | ... AC26: =AC24-AC25
A27: Receita
A28: Receita bruta | B28: brl | C28: =C25*Premissas!$C$6+C26*Premissas!$C$7 | D28: =D25*Premissas!$C$6+D26*Premissas!$C$7 | E28: =E25*Premissas!$C$6+E26*Premissas!$C$7 | F28: =F25*Premissas!$C$6+F26*Premissas!$C$7 | G28: =G25*Premissas!$C$6+G26*Premissas!$C$7 | H28: =H25*Premissas!$C$6+H26*Premissas!$C$7 | I28: =I25*Premissas!$C$6+I26*Premissas!$C$7 | J28: =J25*Premissas!$C$6+J26*Premissas!$C$7 | ... AC28: =AC25*Premissas!$C$6+AC26*Premissas!$C$7
A29: Taxa de pagamento | B29: brl | C29: =C28*(Premissas!$C$8*Premissas!$C$9+(1-Premissas!$C$8)*Premissas!$C$10) | D29: =D28*(Premissas!$C$8*Premissas!$C$9+(1-Premissas!$C$8)*Premissas!$C$10) | E29: =E28*(Premissas!$C$8*Premissas!$C$9+(1-Premissas!$C$8)*Premissas!$C$10) | F29: =F28*(Premissas!$C$8*Premissas!$C$9+(1-Premissas!$C$8)*Premissas!$C$10) | G29: =G28*(Premissas!$C$8*Premissas!$C$9+(1-Premissas!$C$8)*Premissas!$C$10) | H29: =H28*(Premissas!$C$8*Premissas!$C$9+(1-Premissas!$C$8)*Premissas!$C$10) | I29: =I28*(Premissas!$C$8*Premissas!$C$9+(1-Premissas!$C$8)*Premissas!$C$10) | J29: =J28*(Premissas!$C$8*Premissas!$C$9+(1-Premissas!$C$8)*Premissas!$C$10) | ... AC29: =AC28*(Premissas!$C$8*Premissas!$C$9+(1-Premissas!$C$8)*Premissas!$C$10)
A30: Simples Nacional | B30: brl | C30: =C28*Premissas!$C$11 | D30: =D28*Premissas!$C$11 | E30: =E28*Premissas!$C$11 | F30: =F28*Premissas!$C$11 | G30: =G28*Premissas!$C$11 | H30: =H28*Premissas!$C$11 | I30: =I28*Premissas!$C$11 | J30: =J28*Premissas!$C$11 | ... AC30: =AC28*Premissas!$C$11
A31: Receita líquida | B31: brl | C31: =C28-C29-C30 | D31: =D28-D29-D30 | E31: =E28-E29-E30 | F31: =F28-F29-F30 | G31: =G28-G29-G30 | H31: =H28-H29-H30 | I31: =I28-I29-I30 | J31: =J28-J29-J30 | ... AC31: =AC28-AC29-AC30
A32: Custos em dinheiro
A33: Supabase | B33: brl | C33: =(Premissas!$C$12+IF(C17>Premissas!$C$29,Premissas!$C$30,IF(C17>Premissas!$C$27,Premissas!$C$28,IF(C17>Premissas!$C$25,Premissas!$C$26,0))))*Premissas!$C$5 | D33: =(Premissas!$C$12+IF(D17>Premissas!$C$29,Premissas!$C$30,IF(D17>Premissas!$C$27,Premissas!$C$28,IF(D17>Premissas!$C$25,Premissas!$C$26,0))))*Premissas!$C$5 | E33: =(Premissas!$C$12+IF(E17>Premissas!$C$29,Premissas!$C$30,IF(E17>Premissas!$C$27,Premissas!$C$28,IF(E17>Premissas!$C$25,Premissas!$C$26,0))))*Premissas!$C$5 | F33: =(Premissas!$C$12+IF(F17>Premissas!$C$29,Premissas!$C$30,IF(F17>Premissas!$C$27,Premissas!$C$28,IF(F17>Premissas!$C$25,Premissas!$C$26,0))))*Premissas!$C$5 | G33: =(Premissas!$C$12+IF(G17>Premissas!$C$29,Premissas!$C$30,IF(G17>Premissas!$C$27,Premissas!$C$28,IF(G17>Premissas!$C$25,Premissas!$C$26,0))))*Premissas!$C$5 | H33: =(Premissas!$C$12+IF(H17>Premissas!$C$29,Premissas!$C$30,IF(H17>Premissas!$C$27,Premissas!$C$28,IF(H17>Premissas!$C$25,Premissas!$C$26,0))))*Premissas!$C$5 | I33: =(Premissas!$C$12+IF(I17>Premissas!$C$29,Premissas!$C$30,IF(I17>Premissas!$C$27,Premissas!$C$28,IF(I17>Premissas!$C$25,Premissas!$C$26,0))))*Premissas!$C$5 | J33: =(Premissas!$C$12+IF(J17>Premissas!$C$29,Premissas!$C$30,IF(J17>Premissas!$C$27,Premissas!$C$28,IF(J17>Premissas!$C$25,Premissas!$C$26,0))))*Premissas!$C$5 | ... AC33: =(Premissas!$C$12+IF(AC17>Premissas!$C$29,Premissas!$C$30,IF(AC17>Premissas!$C$27,Premissas!$C$28,IF(AC17>Premissas!$C$25,Premissas!$C$26,0))))*Premissas!$C$5
A34: Vercel | B34: brl | C34: =(Premissas!$C$13+MAX(0,C17*Premissas!$C$15-Premissas!$C$14))*Premissas!$C$5 | D34: =(Premissas!$C$13+MAX(0,D17*Premissas!$C$15-Premissas!$C$14))*Premissas!$C$5 | E34: =(Premissas!$C$13+MAX(0,E17*Premissas!$C$15-Premissas!$C$14))*Premissas!$C$5 | F34: =(Premissas!$C$13+MAX(0,F17*Premissas!$C$15-Premissas!$C$14))*Premissas!$C$5 | G34: =(Premissas!$C$13+MAX(0,G17*Premissas!$C$15-Premissas!$C$14))*Premissas!$C$5 | H34: =(Premissas!$C$13+MAX(0,H17*Premissas!$C$15-Premissas!$C$14))*Premissas!$C$5 | I34: =(Premissas!$C$13+MAX(0,I17*Premissas!$C$15-Premissas!$C$14))*Premissas!$C$5 | J34: =(Premissas!$C$13+MAX(0,J17*Premissas!$C$15-Premissas!$C$14))*Premissas!$C$5 | ... AC34: =(Premissas!$C$13+MAX(0,AC17*Premissas!$C$15-Premissas!$C$14))*Premissas!$C$5
A35: Contabilidade e INSS do pró-labore | B35: brl | C35: =Premissas!$C$16+Premissas!$C$17*Premissas!$C$18 | D35: =Premissas!$C$16+Premissas!$C$17*Premissas!$C$18 | E35: =Premissas!$C$16+Premissas!$C$17*Premissas!$C$18 | F35: =Premissas!$C$16+Premissas!$C$17*Premissas!$C$18 | G35: =Premissas!$C$16+Premissas!$C$17*Premissas!$C$18 | H35: =Premissas!$C$16+Premissas!$C$17*Premissas!$C$18 | I35: =Premissas!$C$16+Premissas!$C$17*Premissas!$C$18 | J35: =Premissas!$C$16+Premissas!$C$17*Premissas!$C$18 | ... AC35: =Premissas!$C$16+Premissas!$C$17*Premissas!$C$18
A36: Domínio e e-mail próprio | B36: brl | C36: =Premissas!$C$19+Premissas!$C$20 | D36: =Premissas!$C$19+Premissas!$C$20 | E36: =Premissas!$C$19+Premissas!$C$20 | F36: =Premissas!$C$19+Premissas!$C$20 | G36: =Premissas!$C$19+Premissas!$C$20 | H36: =Premissas!$C$19+Premissas!$C$20 | I36: =Premissas!$C$19+Premissas!$C$20 | J36: =Premissas!$C$19+Premissas!$C$20 | ... AC36: =Premissas!$C$19+Premissas!$C$20
A37: Resend e Sentry (quando passam do grátis) | B37: brl | C37: =(IF(C17>Premissas!$C$22,Premissas!$C$21,0)+IF(C17>Premissas!$C$24,Premissas!$C$23,0))*Premissas!$C$5 | D37: =(IF(D17>Premissas!$C$22,Premissas!$C$21,0)+IF(D17>Premissas!$C$24,Premissas!$C$23,0))*Premissas!$C$5 | E37: =(IF(E17>Premissas!$C$22,Premissas!$C$21,0)+IF(E17>Premissas!$C$24,Premissas!$C$23,0))*Premissas!$C$5 | F37: =(IF(F17>Premissas!$C$22,Premissas!$C$21,0)+IF(F17>Premissas!$C$24,Premissas!$C$23,0))*Premissas!$C$5 | G37: =(IF(G17>Premissas!$C$22,Premissas!$C$21,0)+IF(G17>Premissas!$C$24,Premissas!$C$23,0))*Premissas!$C$5 | H37: =(IF(H17>Premissas!$C$22,Premissas!$C$21,0)+IF(H17>Premissas!$C$24,Premissas!$C$23,0))*Premissas!$C$5 | I37: =(IF(I17>Premissas!$C$22,Premissas!$C$21,0)+IF(I17>Premissas!$C$24,Premissas!$C$23,0))*Premissas!$C$5 | J37: =(IF(J17>Premissas!$C$22,Premissas!$C$21,0)+IF(J17>Premissas!$C$24,Premissas!$C$23,0))*Premissas!$C$5 | ... AC37: =(IF(AC17>Premissas!$C$22,Premissas!$C$21,0)+IF(AC17>Premissas!$C$24,Premissas!$C$23,0))*Premissas!$C$5
A38: Rua: transporte | B38: brl | C38: =C7*Premissas!$C$31 | D38: =D7*Premissas!$C$31 | E38: =E7*Premissas!$C$31 | F38: =F7*Premissas!$C$31 | G38: =G7*Premissas!$C$31 | H38: =H7*Premissas!$C$31 | I38: =I7*Premissas!$C$31 | J38: =J7*Premissas!$C$31 | ... AC38: =AC7*Premissas!$C$31
A39: Conteúdo e material | B39: brl | C39: =Premissas!$C$32 | D39: =Premissas!$C$32 | E39: =Premissas!$C$32 | F39: =Premissas!$C$32 | G39: =Premissas!$C$32 | H39: =Premissas!$C$32 | I39: =Premissas!$C$32 | J39: =Premissas!$C$32 | ... AC39: =Premissas!$C$32
A40: Total de custos | B40: brl | C40: =SUM(C33:C39) | D40: =SUM(D33:D39) | E40: =SUM(E33:E39) | F40: =SUM(F33:F39) | G40: =SUM(G33:G39) | H40: =SUM(H33:H39) | I40: =SUM(I33:I39) | J40: =SUM(J33:J39) | ... AC40: =SUM(AC33:AC39)
A41: Resultado operacional | B41: brl | C41: =C31-C40 | D41: =D31-D40 | E41: =E31-E40 | F41: =F31-F40 | G41: =G31-G40 | H41: =H31-H40 | I41: =I31-I40 | J41: =J31-J40 | ... AC41: =AC31-AC40
...

Sheet Metas
A1: CICLO · Metas de rua: quantas abordagens por dia para chegar lá
A2: Conta de trás para frente, sem indicação e sem parceiros (por isso é conservadora). Muda com as premissas.
A4: Prazo para atingir a meta (meses de rua) | C4: 9
A5: Dias de rua por mês | C5: 20
A6: Custo fixo mensal estável (R$) | C6: =(Premissas!$C$12+Premissas!$C$13)*Premissas!$C$5+Premissas!$C$16+Premissas!$C$17*Premissas!$C$18+Premissas!$C$19+Premissas!$C$20+Premissas!$C$32
A8: Meta de resultado (R$/mês) | B8: Cenário | C8: Receita líquida por pagante | D8: Pagantes | E8: Contas a criar | F8: Conversas | G8: Abordagens | H8: Abordagens por dia
A9: 0 | B9: Pessimista | C9: =Pessimista!C63 | D9: =ROUNDUP(($A9+$C$6)/C9,0) | E9: =ROUNDUP(D9/Premissas!$B$50,0) | F9: =ROUNDUP(E9/Premissas!$B$48,0) | G9: =ROUNDUP(F9/Premissas!$B$47,0) | H9: =G9/($C$4*$C$5)
A10: 0 | B10: Base | C10: =Base!C63 | D10: =ROUNDUP(($A10+$C$6)/C10,0) | E10: =ROUNDUP(D10/Premissas!$C$50,0) | F10: =ROUNDUP(E10/Premissas!$C$48,0) | G10: =ROUNDUP(F10/Premissas!$C$47,0) | H10: =G10/($C$4*$C$5)
A11: 0 | B11: Otimista | C11: =Otimista!C63 | D11: =ROUNDUP(($A11+$C$6)/C11,0) | E11: =ROUNDUP(D11/Premissas!$D$50,0) | F11: =ROUNDUP(E11/Premissas!$D$48,0) | G11: =ROUNDUP(F11/Premissas!$D$47,0) | H11: =G11/($C$4*$C$5)
A12: 1000 | B12: Pessimista | C12: =Pessimista!C63 | D12: =ROUNDUP(($A12+$C$6)/C12,0) | E12: =ROUNDUP(D12/Premissas!$B$50,0) | F12: =ROUNDUP(E12/Premissas!$B$48,0) | G12: =ROUNDUP(F12/Premissas!$B$47,0) | H12: =G12/($C$4*$C$5)
A13: 1000 | B13: Base | C13: =Base!C63 | D13: =ROUNDUP(($A13+$C$6)/C13,0) | E13: =ROUNDUP(D13/Premissas!$C$50,0) | F13: =ROUNDUP(E13/Premissas!$C$48,0) | G13: =ROUNDUP(F13/Premissas!$C$47,0) | H13: =G13/($C$4*$C$5)
A14: 1000 | B14: Otimista | C14: =Otimista!C63 | D14: =ROUNDUP(($A14+$C$6)/C14,0) | E14: =ROUNDUP(D14/Premissas!$D$50,0) | F14: =ROUNDUP(E14/Premissas!$D$48,0) | G14: =ROUNDUP(F14/Premissas!$D$47,0) | H14: =G14/($C$4*$C$5)
A15: 3000 | B15: Pessimista | C15: =Pessimista!C63 | D15: =ROUNDUP(($A15+$C$6)/C15,0) | E15: =ROUNDUP(D15/Premissas!$B$50,0) | F15: =ROUNDUP(E15/Premissas!$B$48,0) | G15: =ROUNDUP(F15/Premissas!$B$47,0) | H15: =G15/($C$4*$C$5)
A16: 3000 | B16: Base | C16: =Base!C63 | D16: =ROUNDUP(($A16+$C$6)/C16,0) | E16: =ROUNDUP(D16/Premissas!$C$50,0) | F16: =ROUNDUP(E16/Premissas!$C$48,0) | G16: =ROUNDUP(F16/Premissas!$C$47,0) | H16: =G16/($C$4*$C$5)
A17: 3000 | B17: Otimista | C17: =Otimista!C63 | D17: =ROUNDUP(($A17+$C$6)/C17,0) | E17: =ROUNDUP(D17/Premissas!$D$50,0) | F17: =ROUNDUP(E17/Premissas!$D$48,0) | G17: =ROUNDUP(F17/Premissas!$D$47,0) | H17: =G17/($C$4*$C$5)
A18: 5000 | B18: Pessimista | C18: =Pessimista!C63 | D18: =ROUNDUP(($A18+$C$6)/C18,0) | E18: =ROUNDUP(D18/Premissas!$B$50,0) | F18: =ROUNDUP(E18/Premissas!$B$48,0) | G18: =ROUNDUP(F18/Premissas!$B$47,0) | H18: =G18/($C$4*$C$5)
A19: 5000 | B19: Base | C19: =Base!C63 | D19: =ROUNDUP(($A19+$C$6)/C19,0) | E19: =ROUNDUP(D19/Premissas!$C$50,0) | F19: =ROUNDUP(E19/Premissas!$C$48,0) | G19: =ROUNDUP(F19/Premissas!$C$47,0) | H19: =G19/($C$4*$C$5)
A20: 5000 | B20: Otimista | C20: =Otimista!C63 | D20: =ROUNDUP(($A20+$C$6)/C20,0) | E20: =ROUNDUP(D20/Premissas!$D$50,0) | F20: =ROUNDUP(E20/Premissas!$D$48,0) | G20: =ROUNDUP(F20/Premissas!$D$47,0) | H20: =G20/($C$4*$C$5)
A22: Meta 0 = ponto de equilíbrio (cobre o custo fixo). Não conta o seu tempo nem os pagantes que saem no caminho.

Sheet Infra
A1: CICLO · Quantas contas cabem antes de a infraestrutura custar mais
A3: Premissa de consumo por conta | C3: Valor | E3: Fonte / nota
A4: Requisições (funções) por conta por mês | C4: 10000 | E4: [E] painel da equipe + página pública de agendamento + rotinas do Motor. Medir na Vercel depois do alpha
A5: CPU ativa por requisição (ms) | C5: 50 | E5: [E] só o tempo de CPU, não a espera do banco. Medir na Vercel
A6: MB de banco por agendamento (tudo incluído) | C6: 0.005 | E6: [M] agendamento 0,8 KB + cliente 1,2 KB + previsão, auditoria e comanda. 5 KB é o teto seguro
A7: Agendamentos por conta por mês | C7: 400 | E7: [E] 2 profissionais x 8 por dia x 25 dias
A8: MB da base de clientes importada por conta | C8: 0.5 | E8: [M] ~400 clientes x 1,2 KB
A9: Idade média das contas (meses) | C9: 12 | E9: Quanto mais antiga, mais o banco pesa
A10: MB de banco da plataforma vazia | C10: 80 | E10: [M] banco local medido: 82 MB
A11: MB transferidos por conta por mês (Vercel) | C11: 150 | E11: [E] muito abaixo de 1 TB até milhares de contas
A12: Uso Vercel por conta (US$/mês) | C12: =C4*0.6/1000000+C4*C5/3600000*0.128 | E12: [P] US$ 0,60 por milhão de chamadas + US$ 0,128 por hora de CPU ativa
A14: MB de banco por conta por mês | C14: =C6*C7
A15: MB de banco por conta na idade média | C15: =C8+C14*C9
A17: Limite de cada plano grátis: até quantas contas
A18: Supabase Free: 500 MB de banco | C18: =(500-C10)/C15 | E18: Sem backup e pausa após 1 semana sem uso [P]. Não serve para cliente pagando
A19: Vercel Hobby: 1 milhão de chamadas | C19: =1000000/C4 | E19: [P] Hobby é só uso pessoal e não comercial
A20: Vercel Hobby: 4 horas de CPU ativa | C20: =4*3600000/(C4*C5) | E20: [P] costuma ser o limite que aperta primeiro
A21: Vercel Pro: 1 TB de transferência | C21: =1000000/C11 | E21: [P] praticamente nunca aperta
A22: Supabase Pro: 8 GB de banco incluídos | C22: =(8*1024-C10)/C15 | E22: [P] depois cobra US$ 0,125 por GB, ou seja, centavos
A23: Resend grátis: 3.000 e-mails por mês | C23: =Premissas!C22 | E23: Vem das Premissas
A26: Contas | C26: Banco (GB) | D26: Chamadas/mês (mi) | E26: Vercel (US$) | F26: Supabase (US$) | G26: Total (US$) | H26: Total (R$) | I26: R$ por conta
A27: 10 | C27: =(C$10+A27*C$15)/1024 | D27: =A27*C$4/1000000 | E27: =Premissas!$C$13+MAX(0,A27*C$12-Premissas!$C$14) | F27: =Premissas!$C$12+IF(A27>Premissas!$C$29,Premissas!$C$30,IF(A27>Premissas!$C$27,Premissas!$C$28,IF(A27>Premissas!$C$25,Premissas!$C$26,0)))+MAX(0,C27-8)*0.125 | G27: =E27+F27 | H27: =G27*Premissas!$C$5 | I27: =H27/A27
A28: 25 | C28: =(C$10+A28*C$15)/1024 | D28: =A28*C$4/1000000 | E28: =Premissas!$C$13+MAX(0,A28*C$12-Premissas!$C$14) | F28: =Premissas!$C$12+IF(A28>Premissas!$C$29,Premissas!$C$30,IF(A28>Premissas!$C$27,Premissas!$C$28,IF(A28>Premissas!$C$25,Premissas!$C$26,0)))+MAX(0,C28-8)*0.125 | G28: =E28+F28 | H28: =G28*Premissas!$C$5 | I28: =H28/A28
A29: 40 | C29: =(C$10+A29*C$15)/1024 | D29: =A29*C$4/1000000 | E29: =Premissas!$C$13+MAX(0,A29*C$12-Premissas!$C$14) | F29: =Premissas!$C$12+IF(A29>Premissas!$C$29,Premissas!$C$30,IF(A29>Premissas!$C$27,Premissas!$C$28,IF(A29>Premissas!$C$25,Premissas!$C$26,0)))+MAX(0,C29-8)*0.125 | G29: =E29+F29 | H29: =G29*Premissas!$C$5 | I29: =H29/A29
